INFO _internal.py:113  * Running on http://127.0.0.1:5000/ (Press CTRL+C to quit)
ERROR demo.py:11 error,msg
WARNING demo.py:12 warn msg
INFO _internal.py:113 127.0.0.1 - - [21/Sep/2020 15:02:47] "[37mGET /api/v1.0/index HTTP/1.1[0m" 200 -


INFO _internal.py:113  * Running on http://127.0.0.1:5000/ (Press CTRL+C to quit)
ERROR demo.py:11 error,msg
WARNING demo.py:12 warn msg
INFO demo.py:13 info msg
DEBUG demo.py:14 debug msg
INFO _internal.py:113 127.0.0.1 - - [21/Sep/2020 15:03:51] "[37mGET /api/v1.0/index HTTP/1.1[0m" 200 -
ERROR __init__.py:98 Error: Directory migrations already exists and is not empty
ERROR __init__.py:98 Error: Directory migrations already exists and is not empty
INFO _internal.py:113  * Running on http://127.0.0.1:5000/ (Press CTRL+C to quit)
ERROR app.py:1891 Exception on /static/html/index.html [GET]
Traceback (most recent call last):
  File "/Users/caoting/.virtualenvs/Flask_iHome/lib/python3.8/site-packages/redis/connection.py", line 559, in connect
    sock = self._connect()
  File "/Users/caoting/.virtualenvs/Flask_iHome/lib/python3.8/site-packages/redis/connection.py", line 615, in _connect
    raise err
  File "/Users/caoting/.virtualenvs/Flask_iHome/lib/python3.8/site-packages/redis/connection.py", line 603, in _connect
    sock.connect(socket_address)
ConnectionRefusedError: [Errno 61] Connection refused

During handling of the above exception, another exception occurred:

Traceback (most recent call last):
  File "/Users/caoting/.virtualenvs/Flask_iHome/lib/python3.8/site-packages/flask/app.py", line 2446, in wsgi_app
    ctx.push()
  File "/Users/caoting/.virtualenvs/Flask_iHome/lib/python3.8/site-packages/flask/ctx.py", line 390, in push
    self.session = session_interface.open_session(self.app, self.request)
  File "/Users/caoting/.virtualenvs/Flask_iHome/lib/python3.8/site-packages/flask_session/sessions.py", line 132, in open_session
    val = self.redis.get(self.key_prefix + sid)
  File "/Users/caoting/.virtualenvs/Flask_iHome/lib/python3.8/site-packages/redis/client.py", line 1606, in get
    return self.execute_command('GET', name)
  File "/Users/caoting/.virtualenvs/Flask_iHome/lib/python3.8/site-packages/redis/client.py", line 898, in execute_command
    conn = self.connection or pool.get_connection(command_name, **options)
  File "/Users/caoting/.virtualenvs/Flask_iHome/lib/python3.8/site-packages/redis/connection.py", line 1192, in get_connection
    connection.connect()
  File "/Users/caoting/.virtualenvs/Flask_iHome/lib/python3.8/site-packages/redis/connection.py", line 563, in connect
    raise ConnectionError(self._error_message(e))
redis.exceptions.ConnectionError: Error 61 connecting to 127.0.0.1:6379. Connection refused.
ERROR app.py:1975 Request finalizing failed with an error while handling an error
Traceback (most recent call last):
  File "/Users/caoting/.virtualenvs/Flask_iHome/lib/python3.8/site-packages/redis/connection.py", line 559, in connect
    sock = self._connect()
  File "/Users/caoting/.virtualenvs/Flask_iHome/lib/python3.8/site-packages/redis/connection.py", line 615, in _connect
    raise err
  File "/Users/caoting/.virtualenvs/Flask_iHome/lib/python3.8/site-packages/redis/connection.py", line 603, in _connect
    sock.connect(socket_address)
ConnectionRefusedError: [Errno 61] Connection refused

During handling of the above exception, another exception occurred:

Traceback (most recent call last):
  File "/Users/caoting/.virtualenvs/Flask_iHome/lib/python3.8/site-packages/flask/app.py", line 2446, in wsgi_app
    ctx.push()
  File "/Users/caoting/.virtualenvs/Flask_iHome/lib/python3.8/site-packages/flask/ctx.py", line 390, in push
    self.session = session_interface.open_session(self.app, self.request)
  File "/Users/caoting/.virtualenvs/Flask_iHome/lib/python3.8/site-packages/flask_session/sessions.py", line 132, in open_session
    val = self.redis.get(self.key_prefix + sid)
  File "/Users/caoting/.virtualenvs/Flask_iHome/lib/python3.8/site-packages/redis/client.py", line 1606, in get
    return self.execute_command('GET', name)
  File "/Users/caoting/.virtualenvs/Flask_iHome/lib/python3.8/site-packages/redis/client.py", line 898, in execute_command
    conn = self.connection or pool.get_connection(command_name, **options)
  File "/Users/caoting/.virtualenvs/Flask_iHome/lib/python3.8/site-packages/redis/connection.py", line 1192, in get_connection
    connection.connect()
  File "/Users/caoting/.virtualenvs/Flask_iHome/lib/python3.8/site-packages/redis/connection.py", line 563, in connect
    raise ConnectionError(self._error_message(e))
redis.exceptions.ConnectionError: Error 61 connecting to 127.0.0.1:6379. Connection refused.

During handling of the above exception, another exception occurred:

Traceback (most recent call last):
  File "/Users/caoting/.virtualenvs/Flask_iHome/lib/python3.8/site-packages/flask/app.py", line 1970, in finalize_request
    response = self.process_response(response)
  File "/Users/caoting/.virtualenvs/Flask_iHome/lib/python3.8/site-packages/flask/app.py", line 2269, in process_response
    self.session_interface.save_session(self, ctx.session, response)
  File "/Users/caoting/.virtualenvs/Flask_iHome/lib/python3.8/site-packages/flask_session/sessions.py", line 145, in save_session
    if session.modified:
AttributeError: 'NoneType' object has no attribute 'modified'
INFO _internal.py:113 127.0.0.1 - - [21/Sep/2020 16:20:05] "[35m[1mGET /static/html/index.html HTTP/1.1[0m" 500 -
ERROR app.py:1891 Exception on /api/v1.0/index [GET]
Traceback (most recent call last):
  File "/Users/caoting/.virtualenvs/Flask_iHome/lib/python3.8/site-packages/redis/connection.py", line 559, in connect
    sock = self._connect()
  File "/Users/caoting/.virtualenvs/Flask_iHome/lib/python3.8/site-packages/redis/connection.py", line 615, in _connect
    raise err
  File "/Users/caoting/.virtualenvs/Flask_iHome/lib/python3.8/site-packages/redis/connection.py", line 603, in _connect
    sock.connect(socket_address)
ConnectionRefusedError: [Errno 61] Connection refused

During handling of the above exception, another exception occurred:

Traceback (most recent call last):
  File "/Users/caoting/.virtualenvs/Flask_iHome/lib/python3.8/site-packages/flask/app.py", line 2446, in wsgi_app
    ctx.push()
  File "/Users/caoting/.virtualenvs/Flask_iHome/lib/python3.8/site-packages/flask/ctx.py", line 390, in push
    self.session = session_interface.open_session(self.app, self.request)
  File "/Users/caoting/.virtualenvs/Flask_iHome/lib/python3.8/site-packages/flask_session/sessions.py", line 132, in open_session
    val = self.redis.get(self.key_prefix + sid)
  File "/Users/caoting/.virtualenvs/Flask_iHome/lib/python3.8/site-packages/redis/client.py", line 1606, in get
    return self.execute_command('GET', name)
  File "/Users/caoting/.virtualenvs/Flask_iHome/lib/python3.8/site-packages/redis/client.py", line 898, in execute_command
    conn = self.connection or pool.get_connection(command_name, **options)
  File "/Users/caoting/.virtualenvs/Flask_iHome/lib/python3.8/site-packages/redis/connection.py", line 1192, in get_connection
    connection.connect()
  File "/Users/caoting/.virtualenvs/Flask_iHome/lib/python3.8/site-packages/redis/connection.py", line 563, in connect
    raise ConnectionError(self._error_message(e))
redis.exceptions.ConnectionError: Error 61 connecting to 127.0.0.1:6379. Connection refused.
ERROR app.py:1975 Request finalizing failed with an error while handling an error
Traceback (most recent call last):
  File "/Users/caoting/.virtualenvs/Flask_iHome/lib/python3.8/site-packages/redis/connection.py", line 559, in connect
    sock = self._connect()
  File "/Users/caoting/.virtualenvs/Flask_iHome/lib/python3.8/site-packages/redis/connection.py", line 615, in _connect
    raise err
  File "/Users/caoting/.virtualenvs/Flask_iHome/lib/python3.8/site-packages/redis/connection.py", line 603, in _connect
    sock.connect(socket_address)
ConnectionRefusedError: [Errno 61] Connection refused

During handling of the above exception, another exception occurred:

Traceback (most recent call last):
  File "/Users/caoting/.virtualenvs/Flask_iHome/lib/python3.8/site-packages/flask/app.py", line 2446, in wsgi_app
    ctx.push()
  File "/Users/caoting/.virtualenvs/Flask_iHome/lib/python3.8/site-packages/flask/ctx.py", line 390, in push
    self.session = session_interface.open_session(self.app, self.request)
  File "/Users/caoting/.virtualenvs/Flask_iHome/lib/python3.8/site-packages/flask_session/sessions.py", line 132, in open_session
    val = self.redis.get(self.key_prefix + sid)
  File "/Users/caoting/.virtualenvs/Flask_iHome/lib/python3.8/site-packages/redis/client.py", line 1606, in get
    return self.execute_command('GET', name)
  File "/Users/caoting/.virtualenvs/Flask_iHome/lib/python3.8/site-packages/redis/client.py", line 898, in execute_command
    conn = self.connection or pool.get_connection(command_name, **options)
  File "/Users/caoting/.virtualenvs/Flask_iHome/lib/python3.8/site-packages/redis/connection.py", line 1192, in get_connection
    connection.connect()
  File "/Users/caoting/.virtualenvs/Flask_iHome/lib/python3.8/site-packages/redis/connection.py", line 563, in connect
    raise ConnectionError(self._error_message(e))
redis.exceptions.ConnectionError: Error 61 connecting to 127.0.0.1:6379. Connection refused.

During handling of the above exception, another exception occurred:

Traceback (most recent call last):
  File "/Users/caoting/.virtualenvs/Flask_iHome/lib/python3.8/site-packages/flask/app.py", line 1970, in finalize_request
    response = self.process_response(response)
  File "/Users/caoting/.virtualenvs/Flask_iHome/lib/python3.8/site-packages/flask/app.py", line 2269, in process_response
    self.session_interface.save_session(self, ctx.session, response)
  File "/Users/caoting/.virtualenvs/Flask_iHome/lib/python3.8/site-packages/flask_session/sessions.py", line 145, in save_session
    if session.modified:
AttributeError: 'NoneType' object has no attribute 'modified'
INFO _internal.py:113 127.0.0.1 - - [21/Sep/2020 16:20:19] "[35m[1mGET /api/v1.0/index HTTP/1.1[0m" 500 -
ERROR app.py:1891 Exception on /api/v1.0/index [GET]
Traceback (most recent call last):
  File "/Users/caoting/.virtualenvs/Flask_iHome/lib/python3.8/site-packages/redis/connection.py", line 559, in connect
    sock = self._connect()
  File "/Users/caoting/.virtualenvs/Flask_iHome/lib/python3.8/site-packages/redis/connection.py", line 615, in _connect
    raise err
  File "/Users/caoting/.virtualenvs/Flask_iHome/lib/python3.8/site-packages/redis/connection.py", line 603, in _connect
    sock.connect(socket_address)
ConnectionRefusedError: [Errno 61] Connection refused

During handling of the above exception, another exception occurred:

Traceback (most recent call last):
  File "/Users/caoting/.virtualenvs/Flask_iHome/lib/python3.8/site-packages/flask/app.py", line 2446, in wsgi_app
    ctx.push()
  File "/Users/caoting/.virtualenvs/Flask_iHome/lib/python3.8/site-packages/flask/ctx.py", line 390, in push
    self.session = session_interface.open_session(self.app, self.request)
  File "/Users/caoting/.virtualenvs/Flask_iHome/lib/python3.8/site-packages/flask_session/sessions.py", line 132, in open_session
    val = self.redis.get(self.key_prefix + sid)
  File "/Users/caoting/.virtualenvs/Flask_iHome/lib/python3.8/site-packages/redis/client.py", line 1606, in get
    return self.execute_command('GET', name)
  File "/Users/caoting/.virtualenvs/Flask_iHome/lib/python3.8/site-packages/redis/client.py", line 898, in execute_command
    conn = self.connection or pool.get_connection(command_name, **options)
  File "/Users/caoting/.virtualenvs/Flask_iHome/lib/python3.8/site-packages/redis/connection.py", line 1192, in get_connection
    connection.connect()
  File "/Users/caoting/.virtualenvs/Flask_iHome/lib/python3.8/site-packages/redis/connection.py", line 563, in connect
    raise ConnectionError(self._error_message(e))
redis.exceptions.ConnectionError: Error 61 connecting to 127.0.0.1:6379. Connection refused.
ERROR app.py:1975 Request finalizing failed with an error while handling an error
Traceback (most recent call last):
  File "/Users/caoting/.virtualenvs/Flask_iHome/lib/python3.8/site-packages/redis/connection.py", line 559, in connect
    sock = self._connect()
  File "/Users/caoting/.virtualenvs/Flask_iHome/lib/python3.8/site-packages/redis/connection.py", line 615, in _connect
    raise err
  File "/Users/caoting/.virtualenvs/Flask_iHome/lib/python3.8/site-packages/redis/connection.py", line 603, in _connect
    sock.connect(socket_address)
ConnectionRefusedError: [Errno 61] Connection refused

During handling of the above exception, another exception occurred:

Traceback (most recent call last):
  File "/Users/caoting/.virtualenvs/Flask_iHome/lib/python3.8/site-packages/flask/app.py", line 2446, in wsgi_app
    ctx.push()
  File "/Users/caoting/.virtualenvs/Flask_iHome/lib/python3.8/site-packages/flask/ctx.py", line 390, in push
    self.session = session_interface.open_session(self.app, self.request)
  File "/Users/caoting/.virtualenvs/Flask_iHome/lib/python3.8/site-packages/flask_session/sessions.py", line 132, in open_session
    val = self.redis.get(self.key_prefix + sid)
  File "/Users/caoting/.virtualenvs/Flask_iHome/lib/python3.8/site-packages/redis/client.py", line 1606, in get
    return self.execute_command('GET', name)
  File "/Users/caoting/.virtualenvs/Flask_iHome/lib/python3.8/site-packages/redis/client.py", line 898, in execute_command
    conn = self.connection or pool.get_connection(command_name, **options)
  File "/Users/caoting/.virtualenvs/Flask_iHome/lib/python3.8/site-packages/redis/connection.py", line 1192, in get_connection
    connection.connect()
  File "/Users/caoting/.virtualenvs/Flask_iHome/lib/python3.8/site-packages/redis/connection.py", line 563, in connect
    raise ConnectionError(self._error_message(e))
redis.exceptions.ConnectionError: Error 61 connecting to 127.0.0.1:6379. Connection refused.

During handling of the above exception, another exception occurred:

Traceback (most recent call last):
  File "/Users/caoting/.virtualenvs/Flask_iHome/lib/python3.8/site-packages/flask/app.py", line 1970, in finalize_request
    response = self.process_response(response)
  File "/Users/caoting/.virtualenvs/Flask_iHome/lib/python3.8/site-packages/flask/app.py", line 2269, in process_response
    self.session_interface.save_session(self, ctx.session, response)
  File "/Users/caoting/.virtualenvs/Flask_iHome/lib/python3.8/site-packages/flask_session/sessions.py", line 145, in save_session
    if session.modified:
AttributeError: 'NoneType' object has no attribute 'modified'
INFO _internal.py:113 127.0.0.1 - - [21/Sep/2020 16:20:21] "[35m[1mGET /api/v1.0/index HTTP/1.1[0m" 500 -
INFO _internal.py:113  * Running on http://127.0.0.1:5000/ (Press CTRL+C to quit)
ERROR app.py:1891 Exception on /api/v1.0/index [GET]
Traceback (most recent call last):
  File "/Users/caoting/.virtualenvs/Flask_iHome/lib/python3.8/site-packages/redis/connection.py", line 559, in connect
    sock = self._connect()
  File "/Users/caoting/.virtualenvs/Flask_iHome/lib/python3.8/site-packages/redis/connection.py", line 615, in _connect
    raise err
  File "/Users/caoting/.virtualenvs/Flask_iHome/lib/python3.8/site-packages/redis/connection.py", line 603, in _connect
    sock.connect(socket_address)
ConnectionRefusedError: [Errno 61] Connection refused

During handling of the above exception, another exception occurred:

Traceback (most recent call last):
  File "/Users/caoting/.virtualenvs/Flask_iHome/lib/python3.8/site-packages/flask/app.py", line 2446, in wsgi_app
    ctx.push()
  File "/Users/caoting/.virtualenvs/Flask_iHome/lib/python3.8/site-packages/flask/ctx.py", line 390, in push
    self.session = session_interface.open_session(self.app, self.request)
  File "/Users/caoting/.virtualenvs/Flask_iHome/lib/python3.8/site-packages/flask_session/sessions.py", line 132, in open_session
    val = self.redis.get(self.key_prefix + sid)
  File "/Users/caoting/.virtualenvs/Flask_iHome/lib/python3.8/site-packages/redis/client.py", line 1606, in get
    return self.execute_command('GET', name)
  File "/Users/caoting/.virtualenvs/Flask_iHome/lib/python3.8/site-packages/redis/client.py", line 898, in execute_command
    conn = self.connection or pool.get_connection(command_name, **options)
  File "/Users/caoting/.virtualenvs/Flask_iHome/lib/python3.8/site-packages/redis/connection.py", line 1192, in get_connection
    connection.connect()
  File "/Users/caoting/.virtualenvs/Flask_iHome/lib/python3.8/site-packages/redis/connection.py", line 563, in connect
    raise ConnectionError(self._error_message(e))
redis.exceptions.ConnectionError: Error 61 connecting to 127.0.0.1:6379. Connection refused.
ERROR app.py:1975 Request finalizing failed with an error while handling an error
Traceback (most recent call last):
  File "/Users/caoting/.virtualenvs/Flask_iHome/lib/python3.8/site-packages/redis/connection.py", line 559, in connect
    sock = self._connect()
  File "/Users/caoting/.virtualenvs/Flask_iHome/lib/python3.8/site-packages/redis/connection.py", line 615, in _connect
    raise err
  File "/Users/caoting/.virtualenvs/Flask_iHome/lib/python3.8/site-packages/redis/connection.py", line 603, in _connect
    sock.connect(socket_address)
ConnectionRefusedError: [Errno 61] Connection refused

During handling of the above exception, another exception occurred:

Traceback (most recent call last):
  File "/Users/caoting/.virtualenvs/Flask_iHome/lib/python3.8/site-packages/flask/app.py", line 2446, in wsgi_app
    ctx.push()
  File "/Users/caoting/.virtualenvs/Flask_iHome/lib/python3.8/site-packages/flask/ctx.py", line 390, in push
    self.session = session_interface.open_session(self.app, self.request)
  File "/Users/caoting/.virtualenvs/Flask_iHome/lib/python3.8/site-packages/flask_session/sessions.py", line 132, in open_session
    val = self.redis.get(self.key_prefix + sid)
  File "/Users/caoting/.virtualenvs/Flask_iHome/lib/python3.8/site-packages/redis/client.py", line 1606, in get
    return self.execute_command('GET', name)
  File "/Users/caoting/.virtualenvs/Flask_iHome/lib/python3.8/site-packages/redis/client.py", line 898, in execute_command
    conn = self.connection or pool.get_connection(command_name, **options)
  File "/Users/caoting/.virtualenvs/Flask_iHome/lib/python3.8/site-packages/redis/connection.py", line 1192, in get_connection
    connection.connect()
  File "/Users/caoting/.virtualenvs/Flask_iHome/lib/python3.8/site-packages/redis/connection.py", line 563, in connect
    raise ConnectionError(self._error_message(e))
redis.exceptions.ConnectionError: Error 61 connecting to 127.0.0.1:6379. Connection refused.

During handling of the above exception, another exception occurred:

Traceback (most recent call last):
  File "/Users/caoting/.virtualenvs/Flask_iHome/lib/python3.8/site-packages/flask/app.py", line 1970, in finalize_request
    response = self.process_response(response)
  File "/Users/caoting/.virtualenvs/Flask_iHome/lib/python3.8/site-packages/flask/app.py", line 2269, in process_response
    self.session_interface.save_session(self, ctx.session, response)
  File "/Users/caoting/.virtualenvs/Flask_iHome/lib/python3.8/site-packages/flask_session/sessions.py", line 145, in save_session
    if session.modified:
AttributeError: 'NoneType' object has no attribute 'modified'
INFO _internal.py:113 127.0.0.1 - - [21/Sep/2020 16:24:01] "[35m[1mGET /api/v1.0/index HTTP/1.1[0m" 500 -
ERROR demo.py:11 error,msg
WARNING demo.py:12 warn msg
INFO demo.py:13 info msg
DEBUG demo.py:14 debug msg
INFO _internal.py:113 127.0.0.1 - - [21/Sep/2020 16:24:29] "[37mGET /api/v1.0/index HTTP/1.1[0m" 200 -
INFO _internal.py:113 127.0.0.1 - - [21/Sep/2020 16:24:45] "[37mGET /static/html/index.html HTTP/1.1[0m" 200 -
INFO _internal.py:113 127.0.0.1 - - [21/Sep/2020 16:24:45] "[37mGET /static/plugins/bootstrap/css/bootstrap.min.css HTTP/1.1[0m" 200 -
INFO _internal.py:113 127.0.0.1 - - [21/Sep/2020 16:24:45] "[37mGET /static/plugins/font-awesome/css/font-awesome.min.css HTTP/1.1[0m" 200 -
INFO _internal.py:113 127.0.0.1 - - [21/Sep/2020 16:24:45] "[37mGET /static/css/reset.css HTTP/1.1[0m" 200 -
INFO _internal.py:113 127.0.0.1 - - [21/Sep/2020 16:24:45] "[37mGET /static/plugins/swiper/css/swiper.min.css HTTP/1.1[0m" 200 -
INFO _internal.py:113 127.0.0.1 - - [21/Sep/2020 16:24:45] "[37mGET /static/plugins/bootstrap-datepicker/css/bootstrap-datepicker.min.css HTTP/1.1[0m" 200 -
INFO _internal.py:113 127.0.0.1 - - [21/Sep/2020 16:24:45] "[37mGET /static/css/ihome/main.css HTTP/1.1[0m" 200 -
INFO _internal.py:113 127.0.0.1 - - [21/Sep/2020 16:24:45] "[37mGET /static/css/ihome/index.css HTTP/1.1[0m" 200 -
INFO _internal.py:113 127.0.0.1 - - [21/Sep/2020 16:24:45] "[37mGET /static/js/jquery.min.js HTTP/1.1[0m" 200 -
INFO _internal.py:113 127.0.0.1 - - [21/Sep/2020 16:24:45] "[37mGET /static/plugins/bootstrap/js/bootstrap.min.js HTTP/1.1[0m" 200 -
INFO _internal.py:113 127.0.0.1 - - [21/Sep/2020 16:24:45] "[37mGET /static/plugins/swiper/js/swiper.jquery.min.js HTTP/1.1[0m" 200 -
INFO _internal.py:113 127.0.0.1 - - [21/Sep/2020 16:24:45] "[37mGET /static/plugins/bootstrap-datepicker/js/bootstrap-datepicker.min.js HTTP/1.1[0m" 200 -
INFO _internal.py:113 127.0.0.1 - - [21/Sep/2020 16:24:45] "[37mGET /static/plugins/bootstrap-datepicker/locales/bootstrap-datepicker.zh-CN.min.js HTTP/1.1[0m" 200 -
INFO _internal.py:113 127.0.0.1 - - [21/Sep/2020 16:24:45] "[37mGET /static/js/template.js HTTP/1.1[0m" 200 -
INFO _internal.py:113 127.0.0.1 - - [21/Sep/2020 16:24:45] "[37mGET /static/js/ihome/index.js HTTP/1.1[0m" 200 -
INFO _internal.py:113 127.0.0.1 - - [21/Sep/2020 16:24:45] "[37mGET /static/images/logo@128x59.png HTTP/1.1[0m" 200 -
INFO _internal.py:113 127.0.0.1 - - [21/Sep/2020 16:24:45] "[37mGET /static/images/home01.jpg HTTP/1.1[0m" 200 -
INFO _internal.py:113 127.0.0.1 - - [21/Sep/2020 16:24:45] "[37mGET /static/images/home02.jpg HTTP/1.1[0m" 200 -
INFO _internal.py:113 127.0.0.1 - - [21/Sep/2020 16:24:45] "[37mGET /static/images/home03.jpg HTTP/1.1[0m" 200 -
INFO _internal.py:113 127.0.0.1 - - [21/Sep/2020 16:24:45] "[37mGET /static/plugins/font-awesome/fonts/fontawesome-webfont.woff2?v=4.6.3 HTTP/1.1[0m" 200 -
INFO _internal.py:113 127.0.0.1 - - [21/Sep/2020 16:24:49] "[33mGET /static/plugins/swiper/js/maps/swiper.jquery.min.js.map HTTP/1.1[0m" 404 -
INFO _internal.py:113 127.0.0.1 - - [21/Sep/2020 16:24:49] "[37mGET /static/plugins/bootstrap/css/bootstrap.min.css.map HTTP/1.1[0m" 200 -
INFO _internal.py:113  * Running on http://127.0.0.1:5000/ (Press CTRL+C to quit)
ERROR app.py:1891 Exception on /index.html [GET]
Traceback (most recent call last):
  File "/Users/caoting/.virtualenvs/Flask_iHome/lib/python3.8/site-packages/flask/app.py", line 2447, in wsgi_app
    response = self.full_dispatch_request()
  File "/Users/caoting/.virtualenvs/Flask_iHome/lib/python3.8/site-packages/flask/app.py", line 1952, in full_dispatch_request
    rv = self.handle_user_exception(e)
  File "/Users/caoting/.virtualenvs/Flask_iHome/lib/python3.8/site-packages/flask/app.py", line 1821, in handle_user_exception
    reraise(exc_type, exc_value, tb)
  File "/Users/caoting/.virtualenvs/Flask_iHome/lib/python3.8/site-packages/flask/_compat.py", line 39, in reraise
    raise value
  File "/Users/caoting/.virtualenvs/Flask_iHome/lib/python3.8/site-packages/flask/app.py", line 1950, in full_dispatch_request
    rv = self.dispatch_request()
  File "/Users/caoting/.virtualenvs/Flask_iHome/lib/python3.8/site-packages/flask/app.py", line 1936, in dispatch_request
    return self.view_functions[rule.endpoint](**req.view_args)
TypeError: get_html() got an unexpected keyword argument 'html_filr_name'
INFO _internal.py:113 127.0.0.1 - - [21/Sep/2020 16:51:23] "[35m[1mGET /index.html HTTP/1.1[0m" 500 -
ERROR app.py:1891 Exception on /index.html [GET]
Traceback (most recent call last):
  File "/Users/caoting/.virtualenvs/Flask_iHome/lib/python3.8/site-packages/flask/app.py", line 2447, in wsgi_app
    response = self.full_dispatch_request()
  File "/Users/caoting/.virtualenvs/Flask_iHome/lib/python3.8/site-packages/flask/app.py", line 1952, in full_dispatch_request
    rv = self.handle_user_exception(e)
  File "/Users/caoting/.virtualenvs/Flask_iHome/lib/python3.8/site-packages/flask/app.py", line 1821, in handle_user_exception
    reraise(exc_type, exc_value, tb)
  File "/Users/caoting/.virtualenvs/Flask_iHome/lib/python3.8/site-packages/flask/_compat.py", line 39, in reraise
    raise value
  File "/Users/caoting/.virtualenvs/Flask_iHome/lib/python3.8/site-packages/flask/app.py", line 1950, in full_dispatch_request
    rv = self.dispatch_request()
  File "/Users/caoting/.virtualenvs/Flask_iHome/lib/python3.8/site-packages/flask/app.py", line 1936, in dispatch_request
    return self.view_functions[rule.endpoint](**req.view_args)
TypeError: get_html() got an unexpected keyword argument 'html_filr_name'
INFO _internal.py:113 127.0.0.1 - - [21/Sep/2020 16:51:55] "[35m[1mGET /index.html HTTP/1.1[0m" 500 -
INFO _internal.py:113  * Running on http://127.0.0.1:5000/ (Press CTRL+C to quit)
INFO _internal.py:113 127.0.0.1 - - [21/Sep/2020 16:52:08] "[37mGET /index.html HTTP/1.1[0m" 200 -
INFO _internal.py:113 127.0.0.1 - - [21/Sep/2020 16:52:08] "[33mGET /static/plugins/swiper/js/maps/swiper.jquery.min.js.map HTTP/1.1[0m" 404 -
INFO _internal.py:113 127.0.0.1 - - [21/Sep/2020 16:52:16] "[37mGET /register.html HTTP/1.1[0m" 200 -
INFO _internal.py:113 127.0.0.1 - - [21/Sep/2020 16:52:16] "[37mGET /static/css/ihome/register.css HTTP/1.1[0m" 200 -
INFO _internal.py:113 127.0.0.1 - - [21/Sep/2020 16:52:16] "[37mGET /static/js/ihome/register.js HTTP/1.1[0m" 200 -
INFO _internal.py:113 127.0.0.1 - - [21/Sep/2020 16:52:48] "[37mGET /register.html HTTP/1.1[0m" 200 -
INFO _internal.py:113 127.0.0.1 - - [21/Sep/2020 16:52:48] "[37mGET /static/plugins/bootstrap/css/bootstrap.min.css HTTP/1.1[0m" 200 -
INFO _internal.py:113 127.0.0.1 - - [21/Sep/2020 16:52:48] "[37mGET /static/plugins/font-awesome/css/font-awesome.min.css HTTP/1.1[0m" 200 -
INFO _internal.py:113 127.0.0.1 - - [21/Sep/2020 16:52:48] "[37mGET /static/css/reset.css HTTP/1.1[0m" 200 -
INFO _internal.py:113 127.0.0.1 - - [21/Sep/2020 16:52:48] "[37mGET /static/css/ihome/main.css HTTP/1.1[0m" 200 -
INFO _internal.py:113 127.0.0.1 - - [21/Sep/2020 16:52:48] "[37mGET /static/css/ihome/register.css HTTP/1.1[0m" 200 -
INFO _internal.py:113 127.0.0.1 - - [21/Sep/2020 16:52:48] "[37mGET /static/js/jquery.min.js HTTP/1.1[0m" 200 -
INFO _internal.py:113 127.0.0.1 - - [21/Sep/2020 16:52:48] "[37mGET /static/plugins/bootstrap/js/bootstrap.min.js HTTP/1.1[0m" 200 -
INFO _internal.py:113 127.0.0.1 - - [21/Sep/2020 16:52:48] "[37mGET /static/js/ihome/register.js HTTP/1.1[0m" 200 -
INFO _internal.py:113 127.0.0.1 - - [21/Sep/2020 16:52:48] "[37mGET /static/images/logo@128x59.png HTTP/1.1[0m" 200 -
INFO _internal.py:113 127.0.0.1 - - [21/Sep/2020 16:52:48] "[37mGET /static/plugins/font-awesome/fonts/fontawesome-webfont.woff2?v=4.6.3 HTTP/1.1[0m" 200 -
INFO _internal.py:113 127.0.0.1 - - [21/Sep/2020 16:52:48] "[37mGET /static/plugins/bootstrap/css/bootstrap.min.css.map HTTP/1.1[0m" 200 -
INFO _internal.py:113 127.0.0.1 - - [21/Sep/2020 16:57:05] "[36mGET /register.html HTTP/1.1[0m" 304 -
INFO _internal.py:113 127.0.0.1 - - [21/Sep/2020 16:57:16] "[37mGET /my.html HTTP/1.1[0m" 200 -
INFO _internal.py:113 127.0.0.1 - - [21/Sep/2020 16:57:16] "[37mGET /static/plugins/bootstrap-datepicker/css/bootstrap-datepicker.min.css HTTP/1.1[0m" 200 -
INFO _internal.py:113 127.0.0.1 - - [21/Sep/2020 16:57:16] "[37mGET /static/css/ihome/my.css HTTP/1.1[0m" 200 -
INFO _internal.py:113 127.0.0.1 - - [21/Sep/2020 16:57:16] "[37mGET /static/plugins/bootstrap-datepicker/js/bootstrap-datepicker.min.js HTTP/1.1[0m" 200 -
INFO _internal.py:113 127.0.0.1 - - [21/Sep/2020 16:57:16] "[37mGET /static/plugins/bootstrap-datepicker/locales/bootstrap-datepicker.zh-CN.min.js HTTP/1.1[0m" 200 -
INFO _internal.py:113 127.0.0.1 - - [21/Sep/2020 16:57:16] "[37mGET /static/js/ihome/my.js HTTP/1.1[0m" 200 -
INFO _internal.py:113 127.0.0.1 - - [21/Sep/2020 16:57:37] "[36mGET /my.html HTTP/1.1[0m" 304 -
INFO _internal.py:113 127.0.0.1 - - [21/Sep/2020 16:57:39] "[36mGET /my.html HTTP/1.1[0m" 304 -
INFO _internal.py:113 127.0.0.1 - - [21/Sep/2020 16:59:22] "[37mGET /favicon.ico HTTP/1.1[0m" 200 -
INFO _internal.py:113 127.0.0.1 - - [21/Sep/2020 16:59:32] "[37mGET / HTTP/1.1[0m" 200 -
INFO _internal.py:113 127.0.0.1 - - [21/Sep/2020 16:59:32] "[37mGET /static/plugins/swiper/css/swiper.min.css HTTP/1.1[0m" 200 -
INFO _internal.py:113 127.0.0.1 - - [21/Sep/2020 16:59:32] "[37mGET /static/css/ihome/index.css HTTP/1.1[0m" 200 -
INFO _internal.py:113 127.0.0.1 - - [21/Sep/2020 16:59:32] "[37mGET /static/plugins/swiper/js/swiper.jquery.min.js HTTP/1.1[0m" 200 -
INFO _internal.py:113 127.0.0.1 - - [21/Sep/2020 16:59:32] "[37mGET /static/js/template.js HTTP/1.1[0m" 200 -
INFO _internal.py:113 127.0.0.1 - - [21/Sep/2020 16:59:32] "[37mGET /static/js/ihome/index.js HTTP/1.1[0m" 200 -
INFO _internal.py:113 127.0.0.1 - - [21/Sep/2020 16:59:32] "[37mGET /static/images/home01.jpg HTTP/1.1[0m" 200 -
INFO _internal.py:113 127.0.0.1 - - [21/Sep/2020 16:59:32] "[37mGET /static/images/home02.jpg HTTP/1.1[0m" 200 -
INFO _internal.py:113 127.0.0.1 - - [21/Sep/2020 16:59:32] "[37mGET /static/images/home03.jpg HTTP/1.1[0m" 200 -
INFO _internal.py:113 127.0.0.1 - - [21/Sep/2020 16:59:32] "[33mGET /static/plugins/swiper/js/maps/swiper.jquery.min.js.map HTTP/1.1[0m" 404 -
INFO _internal.py:113  * Running on http://127.0.0.1:5000/ (Press CTRL+C to quit)
ERROR demo.py:11 error,msg
WARNING demo.py:12 warn msg
INFO demo.py:13 info msg
DEBUG demo.py:14 debug msg
INFO _internal.py:113 127.0.0.1 - - [22/Sep/2020 13:02:42] "[37mGET /api/v1.0/index HTTP/1.1[0m" 200 -
INFO _internal.py:113 127.0.0.1 - - [22/Sep/2020 13:02:42] "[36mGET /favicon.ico HTTP/1.1[0m" 304 -
ERROR demo.py:11 error,msg
WARNING demo.py:12 warn msg
INFO demo.py:13 info msg
DEBUG demo.py:14 debug msg
INFO _internal.py:113 127.0.0.1 - - [22/Sep/2020 13:02:54] "[37mGET /api/v1.0/index HTTP/1.1[0m" 200 -
ERROR demo.py:11 error,msg
WARNING demo.py:12 warn msg
INFO demo.py:13 info msg
DEBUG demo.py:14 debug msg
INFO _internal.py:113 127.0.0.1 - - [22/Sep/2020 13:03:26] "[37mGET /api/v1.0/index HTTP/1.1[0m" 200 -
INFO _internal.py:113 127.0.0.1 - - [22/Sep/2020 13:03:37] "[37mGET /index.html HTTP/1.1[0m" 200 -
INFO _internal.py:113 127.0.0.1 - - [22/Sep/2020 13:03:37] "[36mGET /static/plugins/bootstrap/css/bootstrap.min.css HTTP/1.1[0m" 304 -
INFO _internal.py:113 127.0.0.1 - - [22/Sep/2020 13:03:37] "[36mGET /static/plugins/font-awesome/css/font-awesome.min.css HTTP/1.1[0m" 304 -
INFO _internal.py:113 127.0.0.1 - - [22/Sep/2020 13:03:37] "[36mGET /static/css/reset.css HTTP/1.1[0m" 304 -
INFO _internal.py:113 127.0.0.1 - - [22/Sep/2020 13:03:37] "[36mGET /static/plugins/swiper/css/swiper.min.css HTTP/1.1[0m" 304 -
INFO _internal.py:113 127.0.0.1 - - [22/Sep/2020 13:03:37] "[36mGET /static/plugins/bootstrap-datepicker/css/bootstrap-datepicker.min.css HTTP/1.1[0m" 304 -
INFO _internal.py:113 127.0.0.1 - - [22/Sep/2020 13:03:37] "[36mGET /static/css/ihome/main.css HTTP/1.1[0m" 304 -
INFO _internal.py:113 127.0.0.1 - - [22/Sep/2020 13:03:37] "[36mGET /static/css/ihome/index.css HTTP/1.1[0m" 304 -
INFO _internal.py:113 127.0.0.1 - - [22/Sep/2020 13:03:37] "[36mGET /static/js/jquery.min.js HTTP/1.1[0m" 304 -
INFO _internal.py:113 127.0.0.1 - - [22/Sep/2020 13:03:37] "[36mGET /static/plugins/swiper/js/swiper.jquery.min.js HTTP/1.1[0m" 304 -
INFO _internal.py:113 127.0.0.1 - - [22/Sep/2020 13:03:37] "[36mGET /static/plugins/bootstrap/js/bootstrap.min.js HTTP/1.1[0m" 304 -
INFO _internal.py:113 127.0.0.1 - - [22/Sep/2020 13:03:37] "[36mGET /static/plugins/bootstrap-datepicker/js/bootstrap-datepicker.min.js HTTP/1.1[0m" 304 -
INFO _internal.py:113 127.0.0.1 - - [22/Sep/2020 13:03:37] "[36mGET /static/plugins/bootstrap-datepicker/locales/bootstrap-datepicker.zh-CN.min.js HTTP/1.1[0m" 304 -
INFO _internal.py:113 127.0.0.1 - - [22/Sep/2020 13:03:37] "[36mGET /static/js/template.js HTTP/1.1[0m" 304 -
INFO _internal.py:113 127.0.0.1 - - [22/Sep/2020 13:03:37] "[36mGET /static/js/ihome/index.js HTTP/1.1[0m" 304 -
INFO _internal.py:113 127.0.0.1 - - [22/Sep/2020 13:03:37] "[36mGET /static/images/logo@128x59.png HTTP/1.1[0m" 304 -
INFO _internal.py:113 127.0.0.1 - - [22/Sep/2020 13:03:37] "[36mGET /static/images/home01.jpg HTTP/1.1[0m" 304 -
INFO _internal.py:113 127.0.0.1 - - [22/Sep/2020 13:03:37] "[36mGET /static/images/home02.jpg HTTP/1.1[0m" 304 -
INFO _internal.py:113 127.0.0.1 - - [22/Sep/2020 13:03:37] "[36mGET /static/images/home03.jpg HTTP/1.1[0m" 304 -
INFO _internal.py:113 127.0.0.1 - - [22/Sep/2020 13:03:37] "[36mGET /static/plugins/font-awesome/fonts/fontawesome-webfont.woff2?v=4.6.3 HTTP/1.1[0m" 304 -
INFO _internal.py:113 127.0.0.1 - - [22/Sep/2020 13:03:37] "[36mGET /static/plugins/bootstrap/css/bootstrap.min.css.map HTTP/1.1[0m" 304 -
INFO _internal.py:113 127.0.0.1 - - [22/Sep/2020 13:03:37] "[33mGET /static/plugins/swiper/js/maps/swiper.jquery.min.js.map HTTP/1.1[0m" 404 -
INFO _internal.py:113 127.0.0.1 - - [22/Sep/2020 13:04:00] "[37mGET /search.html?aid=&aname=&sd=&ed= HTTP/1.1[0m" 200 -
INFO _internal.py:113 127.0.0.1 - - [22/Sep/2020 13:04:00] "[37mGET /static/css/ihome/search.css HTTP/1.1[0m" 200 -
INFO _internal.py:113 127.0.0.1 - - [22/Sep/2020 13:04:00] "[37mGET /static/js/ihome/search.js HTTP/1.1[0m" 200 -
INFO _internal.py:113 127.0.0.1 - - [22/Sep/2020 13:04:00] "[33mGET /static/images/landlord01.jgp HTTP/1.1[0m" 404 -
INFO _internal.py:113 127.0.0.1 - - [22/Sep/2020 15:16:29] "[37mGET /detail.html?id=1 HTTP/1.1[0m" 200 -
INFO _internal.py:113 127.0.0.1 - - [22/Sep/2020 15:16:29] "[37mGET /static/css/ihome/detail.css HTTP/1.1[0m" 200 -
INFO _internal.py:113 127.0.0.1 - - [22/Sep/2020 15:16:29] "[37mGET /static/js/ihome/detail.js HTTP/1.1[0m" 200 -
INFO _internal.py:113 127.0.0.1 - - [22/Sep/2020 15:16:29] "[37mGET /static/images/landlord01.jpg HTTP/1.1[0m" 200 -
INFO _internal.py:113 127.0.0.1 - - [22/Sep/2020 15:16:29] "[37mGET /static/images/houseicon_sprite.png HTTP/1.1[0m" 200 -
INFO _internal.py:113 127.0.0.1 - - [22/Sep/2020 15:16:29] "[33mGET /static/plugins/swiper/js/maps/swiper.jquery.min.js.map HTTP/1.1[0m" 404 -
INFO _internal.py:113 127.0.0.1 - - [22/Sep/2020 15:16:31] "[33mGET /static/plugins/swiper/js/maps/swiper.jquery.min.js.map HTTP/1.1[0m" 404 -
INFO _internal.py:113 127.0.0.1 - - [22/Sep/2020 15:16:33] "[33mGET /static/plugins/swiper/js/maps/swiper.jquery.min.js.map HTTP/1.1[0m" 404 -
INFO _internal.py:113 127.0.0.1 - - [22/Sep/2020 15:16:34] "[33mGET /static/plugins/swiper/js/maps/swiper.jquery.min.js.map HTTP/1.1[0m" 404 -
INFO _internal.py:113 127.0.0.1 - - [22/Sep/2020 15:16:34] "[33mGET /static/plugins/swiper/js/maps/swiper.jquery.min.js.map HTTP/1.1[0m" 404 -
INFO _internal.py:113 127.0.0.1 - - [22/Sep/2020 15:16:35] "[33mGET /static/plugins/swiper/js/maps/swiper.jquery.min.js.map HTTP/1.1[0m" 404 -
INFO _internal.py:113 127.0.0.1 - - [22/Sep/2020 15:16:35] "[33mGET /static/plugins/swiper/js/maps/swiper.jquery.min.js.map HTTP/1.1[0m" 404 -
INFO _internal.py:113 127.0.0.1 - - [22/Sep/2020 15:16:35] "[33mGET /static/plugins/swiper/js/maps/swiper.jquery.min.js.map HTTP/1.1[0m" 404 -
INFO _internal.py:113 127.0.0.1 - - [22/Sep/2020 15:16:35] "[33mGET /static/plugins/swiper/js/maps/swiper.jquery.min.js.map HTTP/1.1[0m" 404 -
INFO _internal.py:113 127.0.0.1 - - [22/Sep/2020 15:16:35] "[33mGET /static/plugins/swiper/js/maps/swiper.jquery.min.js.map HTTP/1.1[0m" 404 -
INFO _internal.py:113 127.0.0.1 - - [22/Sep/2020 15:16:35] "[33mGET /static/plugins/swiper/js/maps/swiper.jquery.min.js.map HTTP/1.1[0m" 404 -
INFO _internal.py:113 127.0.0.1 - - [22/Sep/2020 15:16:36] "[33mGET /static/plugins/swiper/js/maps/swiper.jquery.min.js.map HTTP/1.1[0m" 404 -
INFO _internal.py:113 127.0.0.1 - - [22/Sep/2020 15:16:36] "[33mGET /static/plugins/swiper/js/maps/swiper.jquery.min.js.map HTTP/1.1[0m" 404 -
INFO _internal.py:113 127.0.0.1 - - [22/Sep/2020 15:16:36] "[33mGET /static/plugins/swiper/js/maps/swiper.jquery.min.js.map HTTP/1.1[0m" 404 -
INFO _internal.py:113 127.0.0.1 - - [22/Sep/2020 15:16:36] "[33mGET /static/plugins/swiper/js/maps/swiper.jquery.min.js.map HTTP/1.1[0m" 404 -
INFO _internal.py:113 127.0.0.1 - - [22/Sep/2020 15:16:36] "[33mGET /static/plugins/swiper/js/maps/swiper.jquery.min.js.map HTTP/1.1[0m" 404 -
INFO _internal.py:113 127.0.0.1 - - [22/Sep/2020 15:16:37] "[33mGET /static/plugins/swiper/js/maps/swiper.jquery.min.js.map HTTP/1.1[0m" 404 -
INFO _internal.py:113 127.0.0.1 - - [22/Sep/2020 15:16:37] "[33mGET /static/plugins/swiper/js/maps/swiper.jquery.min.js.map HTTP/1.1[0m" 404 -
INFO _internal.py:113 127.0.0.1 - - [22/Sep/2020 15:16:37] "[33mGET /static/plugins/swiper/js/maps/swiper.jquery.min.js.map HTTP/1.1[0m" 404 -
INFO _internal.py:113 127.0.0.1 - - [22/Sep/2020 15:16:37] "[33mGET /static/plugins/swiper/js/maps/swiper.jquery.min.js.map HTTP/1.1[0m" 404 -
INFO _internal.py:113 127.0.0.1 - - [22/Sep/2020 15:16:38] "[33mGET /static/plugins/swiper/js/maps/swiper.jquery.min.js.map HTTP/1.1[0m" 404 -
INFO _internal.py:113 127.0.0.1 - - [22/Sep/2020 15:16:39] "[33mGET /static/plugins/swiper/js/maps/swiper.jquery.min.js.map HTTP/1.1[0m" 404 -
INFO _internal.py:113 127.0.0.1 - - [22/Sep/2020 15:16:39] "[33mGET /static/plugins/swiper/js/maps/swiper.jquery.min.js.map HTTP/1.1[0m" 404 -
INFO _internal.py:113  * Running on http://127.0.0.1:5000/ (Press CTRL+C to quit)
INFO _internal.py:113 127.0.0.1 - - [23/Sep/2020 11:36:37] "[33mGET /api/v1.0/iamge_codes/123 HTTP/1.1[0m" 404 -
INFO _internal.py:113 127.0.0.1 - - [23/Sep/2020 11:36:50] "[33mGET /api/v1.0/image_codes/123 HTTP/1.1[0m" 404 -
INFO _internal.py:113 127.0.0.1 - - [23/Sep/2020 11:37:23] "[33mGET /api/v1.0/image_codes/123 HTTP/1.1[0m" 404 -
INFO _internal.py:113 127.0.0.1 - - [23/Sep/2020 11:38:24] "[37mGET /api/v1.0/get_image_codes/123 HTTP/1.1[0m" 200 -
INFO _internal.py:113 127.0.0.1 - - [23/Sep/2020 11:41:28] "[33mGET /api/v1.0/get_image_codes/ HTTP/1.1[0m" 404 -
INFO _internal.py:113 127.0.0.1 - - [23/Sep/2020 11:41:34] "[37mGET /api/v1.0/get_image_codes/asc HTTP/1.1[0m" 200 -
INFO _internal.py:113 127.0.0.1 - - [23/Sep/2020 11:41:37] "[33mGET /api/v1.0/get_image_codes HTTP/1.1[0m" 404 -
INFO _internal.py:113 127.0.0.1 - - [23/Sep/2020 13:01:35] "[33mGET /api/v1.0/image_codes HTTP/1.1[0m" 404 -
INFO _internal.py:113 127.0.0.1 - - [23/Sep/2020 13:01:43] "[33mGET /api/v1.0/image_codes/321 HTTP/1.1[0m" 404 -
INFO _internal.py:113 127.0.0.1 - - [23/Sep/2020 13:01:45] "[33mGET /api/v1.0/image_codes/321 HTTP/1.1[0m" 404 -
INFO _internal.py:113  * Running on http://127.0.0.1:5000/ (Press CTRL+C to quit)
INFO _internal.py:113 127.0.0.1 - - [23/Sep/2020 13:02:05] "[37mGET /api/v1.0/image_codes/321 HTTP/1.1[0m" 200 -
INFO _internal.py:113 127.0.0.1 - - [23/Sep/2020 13:02:55] "[37mGET /api/v1.0/image_codes/1234 HTTP/1.1[0m" 200 -
INFO _internal.py:113 127.0.0.1 - - [23/Sep/2020 13:07:25] "[37mGET /api/v1.0/image_codes/1234 HTTP/1.1[0m" 200 -
INFO _internal.py:113 127.0.0.1 - - [23/Sep/2020 13:08:18] "[37mGET /static/html/index.html HTTP/1.1[0m" 200 -
INFO _internal.py:113 127.0.0.1 - - [23/Sep/2020 13:08:18] "[36mGET /static/plugins/bootstrap/css/bootstrap.min.css HTTP/1.1[0m" 304 -
INFO _internal.py:113 127.0.0.1 - - [23/Sep/2020 13:08:18] "[36mGET /static/plugins/font-awesome/css/font-awesome.min.css HTTP/1.1[0m" 304 -
INFO _internal.py:113 127.0.0.1 - - [23/Sep/2020 13:08:18] "[36mGET /static/css/reset.css HTTP/1.1[0m" 304 -
INFO _internal.py:113 127.0.0.1 - - [23/Sep/2020 13:08:18] "[36mGET /static/plugins/swiper/css/swiper.min.css HTTP/1.1[0m" 304 -
INFO _internal.py:113 127.0.0.1 - - [23/Sep/2020 13:08:18] "[36mGET /static/plugins/bootstrap-datepicker/css/bootstrap-datepicker.min.css HTTP/1.1[0m" 304 -
INFO _internal.py:113 127.0.0.1 - - [23/Sep/2020 13:08:18] "[36mGET /static/css/ihome/main.css HTTP/1.1[0m" 304 -
INFO _internal.py:113 127.0.0.1 - - [23/Sep/2020 13:08:18] "[36mGET /static/css/ihome/index.css HTTP/1.1[0m" 304 -
INFO _internal.py:113 127.0.0.1 - - [23/Sep/2020 13:08:18] "[36mGET /static/js/jquery.min.js HTTP/1.1[0m" 304 -
INFO _internal.py:113 127.0.0.1 - - [23/Sep/2020 13:08:18] "[36mGET /static/plugins/bootstrap/js/bootstrap.min.js HTTP/1.1[0m" 304 -
INFO _internal.py:113 127.0.0.1 - - [23/Sep/2020 13:08:18] "[36mGET /static/plugins/swiper/js/swiper.jquery.min.js HTTP/1.1[0m" 304 -
INFO _internal.py:113 127.0.0.1 - - [23/Sep/2020 13:08:18] "[36mGET /static/plugins/bootstrap-datepicker/js/bootstrap-datepicker.min.js HTTP/1.1[0m" 304 -
INFO _internal.py:113 127.0.0.1 - - [23/Sep/2020 13:08:18] "[36mGET /static/plugins/bootstrap-datepicker/locales/bootstrap-datepicker.zh-CN.min.js HTTP/1.1[0m" 304 -
INFO _internal.py:113 127.0.0.1 - - [23/Sep/2020 13:08:18] "[36mGET /static/js/template.js HTTP/1.1[0m" 304 -
INFO _internal.py:113 127.0.0.1 - - [23/Sep/2020 13:08:18] "[36mGET /static/js/ihome/index.js HTTP/1.1[0m" 304 -
INFO _internal.py:113 127.0.0.1 - - [23/Sep/2020 13:08:18] "[36mGET /static/images/logo@128x59.png HTTP/1.1[0m" 304 -
INFO _internal.py:113 127.0.0.1 - - [23/Sep/2020 13:08:18] "[36mGET /static/images/home01.jpg HTTP/1.1[0m" 304 -
INFO _internal.py:113 127.0.0.1 - - [23/Sep/2020 13:08:18] "[36mGET /static/images/home02.jpg HTTP/1.1[0m" 304 -
INFO _internal.py:113 127.0.0.1 - - [23/Sep/2020 13:08:18] "[36mGET /static/images/home03.jpg HTTP/1.1[0m" 304 -
INFO _internal.py:113 127.0.0.1 - - [23/Sep/2020 13:08:18] "[36mGET /static/plugins/font-awesome/fonts/fontawesome-webfont.woff2?v=4.6.3 HTTP/1.1[0m" 304 -
INFO _internal.py:113 127.0.0.1 - - [23/Sep/2020 13:08:22] "[33mGET /static/plugins/swiper/js/maps/swiper.jquery.min.js.map HTTP/1.1[0m" 404 -
INFO _internal.py:113 127.0.0.1 - - [23/Sep/2020 13:08:22] "[36mGET /static/plugins/bootstrap/css/bootstrap.min.css.map HTTP/1.1[0m" 304 -
INFO _internal.py:113 127.0.0.1 - - [23/Sep/2020 13:08:24] "[36mGET /register.html HTTP/1.1[0m" 304 -
INFO _internal.py:113 127.0.0.1 - - [23/Sep/2020 13:08:24] "[36mGET /static/css/ihome/register.css HTTP/1.1[0m" 304 -
INFO _internal.py:113 127.0.0.1 - - [23/Sep/2020 13:08:24] "[36mGET /static/js/ihome/register.js HTTP/1.1[0m" 304 -
INFO _internal.py:113 127.0.0.1 - - [23/Sep/2020 13:08:33] "[36mGET /index.html HTTP/1.1[0m" 304 -
INFO _internal.py:113 127.0.0.1 - - [23/Sep/2020 13:08:33] "[33mGET /static/plugins/swiper/js/maps/swiper.jquery.min.js.map HTTP/1.1[0m" 404 -
INFO _internal.py:113 127.0.0.1 - - [23/Sep/2020 13:08:40] "[33mGET /static/plugins/swiper/js/maps/swiper.jquery.min.js.map HTTP/1.1[0m" 404 -
INFO _internal.py:113  * Running on http://127.0.0.1:5000/ (Press CTRL+C to quit)
INFO _internal.py:113 127.0.0.1 - - [23/Sep/2020 13:26:49] "[37mGET /index.html HTTP/1.1[0m" 200 -
INFO _internal.py:113 127.0.0.1 - - [23/Sep/2020 13:26:49] "[37mGET /static/plugins/bootstrap/css/bootstrap.min.css HTTP/1.1[0m" 200 -
INFO _internal.py:113 127.0.0.1 - - [23/Sep/2020 13:26:49] "[37mGET /static/plugins/font-awesome/css/font-awesome.min.css HTTP/1.1[0m" 200 -
INFO _internal.py:113 127.0.0.1 - - [23/Sep/2020 13:26:49] "[37mGET /static/css/reset.css HTTP/1.1[0m" 200 -
INFO _internal.py:113 127.0.0.1 - - [23/Sep/2020 13:26:49] "[37mGET /static/plugins/swiper/css/swiper.min.css HTTP/1.1[0m" 200 -
INFO _internal.py:113 127.0.0.1 - - [23/Sep/2020 13:26:49] "[37mGET /static/plugins/bootstrap-datepicker/css/bootstrap-datepicker.min.css HTTP/1.1[0m" 200 -
INFO _internal.py:113 127.0.0.1 - - [23/Sep/2020 13:26:49] "[37mGET /static/css/ihome/main.css HTTP/1.1[0m" 200 -
INFO _internal.py:113 127.0.0.1 - - [23/Sep/2020 13:26:49] "[37mGET /static/css/ihome/index.css HTTP/1.1[0m" 200 -
INFO _internal.py:113 127.0.0.1 - - [23/Sep/2020 13:26:49] "[37mGET /static/js/jquery.min.js HTTP/1.1[0m" 200 -
INFO _internal.py:113 127.0.0.1 - - [23/Sep/2020 13:26:49] "[37mGET /static/plugins/bootstrap/js/bootstrap.min.js HTTP/1.1[0m" 200 -
INFO _internal.py:113 127.0.0.1 - - [23/Sep/2020 13:26:49] "[37mGET /static/plugins/swiper/js/swiper.jquery.min.js HTTP/1.1[0m" 200 -
INFO _internal.py:113 127.0.0.1 - - [23/Sep/2020 13:26:49] "[37mGET /static/plugins/bootstrap-datepicker/js/bootstrap-datepicker.min.js HTTP/1.1[0m" 200 -
INFO _internal.py:113 127.0.0.1 - - [23/Sep/2020 13:26:49] "[37mGET /static/plugins/bootstrap-datepicker/locales/bootstrap-datepicker.zh-CN.min.js HTTP/1.1[0m" 200 -
INFO _internal.py:113 127.0.0.1 - - [23/Sep/2020 13:26:49] "[37mGET /static/js/template.js HTTP/1.1[0m" 200 -
INFO _internal.py:113 127.0.0.1 - - [23/Sep/2020 13:26:49] "[37mGET /static/js/ihome/index.js HTTP/1.1[0m" 200 -
INFO _internal.py:113 127.0.0.1 - - [23/Sep/2020 13:26:49] "[37mGET /static/images/logo@128x59.png HTTP/1.1[0m" 200 -
INFO _internal.py:113 127.0.0.1 - - [23/Sep/2020 13:26:49] "[37mGET /static/images/home01.jpg HTTP/1.1[0m" 200 -
INFO _internal.py:113 127.0.0.1 - - [23/Sep/2020 13:26:49] "[37mGET /static/images/home02.jpg HTTP/1.1[0m" 200 -
INFO _internal.py:113 127.0.0.1 - - [23/Sep/2020 13:26:49] "[37mGET /static/images/home03.jpg HTTP/1.1[0m" 200 -
INFO _internal.py:113 127.0.0.1 - - [23/Sep/2020 13:26:49] "[37mGET /static/plugins/font-awesome/fonts/fontawesome-webfont.woff2?v=4.6.3 HTTP/1.1[0m" 200 -
INFO _internal.py:113 127.0.0.1 - - [23/Sep/2020 13:26:49] "[37mGET /static/plugins/bootstrap/css/bootstrap.min.css.map HTTP/1.1[0m" 200 -
INFO _internal.py:113 127.0.0.1 - - [23/Sep/2020 13:26:49] "[33mGET /static/plugins/swiper/js/maps/swiper.jquery.min.js.map HTTP/1.1[0m" 404 -
INFO _internal.py:113 127.0.0.1 - - [23/Sep/2020 13:27:13] "[36mGET /index.html HTTP/1.1[0m" 304 -
INFO _internal.py:113 127.0.0.1 - - [23/Sep/2020 13:27:13] "[33mGET /static/plugins/swiper/js/maps/swiper.jquery.min.js.map HTTP/1.1[0m" 404 -
INFO _internal.py:113 127.0.0.1 - - [23/Sep/2020 13:27:14] "[37mGET /register.html HTTP/1.1[0m" 200 -
INFO _internal.py:113 127.0.0.1 - - [23/Sep/2020 13:27:14] "[37mGET /static/css/ihome/register.css HTTP/1.1[0m" 200 -
INFO _internal.py:113 127.0.0.1 - - [23/Sep/2020 13:27:14] "[37mGET /static/js/ihome/register.js HTTP/1.1[0m" 200 -
INFO _internal.py:113 127.0.0.1 - - [23/Sep/2020 13:27:14] "[37mGET /api/v1.0/image_codes/7d94476a-d2c5-4e7c-898c-c0ca59ad0289 HTTP/1.1[0m" 200 -
INFO _internal.py:113 127.0.0.1 - - [23/Sep/2020 13:27:53] "[36mGET /register.html HTTP/1.1[0m" 304 -
INFO _internal.py:113 127.0.0.1 - - [23/Sep/2020 13:27:53] "[37mGET /api/v1.0/image_codes/354b34f2-f831-49f1-b9ef-dba25ac3eea1 HTTP/1.1[0m" 200 -
INFO _internal.py:113 127.0.0.1 - - [23/Sep/2020 13:27:53] "[37mGET /favicon.ico HTTP/1.1[0m" 200 -
INFO _internal.py:113 127.0.0.1 - - [23/Sep/2020 13:28:08] "[37mGET /api/v1.0/image_codes/d482c2f4-dfea-4842-8cf4-f60356191bfb HTTP/1.1[0m" 200 -
INFO _internal.py:113 127.0.0.1 - - [23/Sep/2020 13:28:11] "[36mGET /register.html HTTP/1.1[0m" 304 -
INFO _internal.py:113 127.0.0.1 - - [23/Sep/2020 13:28:11] "[37mGET /api/v1.0/image_codes/4cf109a0-7529-4836-bdf8-ee27a567b3a1 HTTP/1.1[0m" 200 -
INFO _internal.py:113 127.0.0.1 - - [23/Sep/2020 13:28:15] "[36mGET /register.html HTTP/1.1[0m" 304 -
INFO _internal.py:113 127.0.0.1 - - [23/Sep/2020 13:28:15] "[37mGET /api/v1.0/image_codes/d8732f67-7628-45d7-bb3a-780ef72f5667 HTTP/1.1[0m" 200 -
INFO _internal.py:113 127.0.0.1 - - [23/Sep/2020 13:28:17] "[37mGET /api/v1.0/image_codes/d6ccefc5-08ed-4eda-92df-c7b6f2b30cb8 HTTP/1.1[0m" 200 -
INFO _internal.py:113 127.0.0.1 - - [23/Sep/2020 14:03:09] "[37mGET /api/v1.0/image_codes/5d3f0c56-bf43-4cf4-b702-974640c0df37 HTTP/1.1[0m" 200 -
INFO _internal.py:113 127.0.0.1 - - [23/Sep/2020 14:03:11] "[36mGET /register.html HTTP/1.1[0m" 304 -
INFO _internal.py:113 127.0.0.1 - - [23/Sep/2020 14:03:11] "[37mGET /api/v1.0/image_codes/20f9c341-6a99-42e3-9f77-52e6792acf8b HTTP/1.1[0m" 200 -
INFO _internal.py:113 127.0.0.1 - - [23/Sep/2020 14:03:13] "[36mGET /register.html HTTP/1.1[0m" 304 -
INFO _internal.py:113 127.0.0.1 - - [23/Sep/2020 14:03:13] "[37mGET /api/v1.0/image_codes/d4304308-7c4b-4d98-936a-c918a9327ed7 HTTP/1.1[0m" 200 -
INFO _internal.py:113 127.0.0.1 - - [23/Sep/2020 14:03:15] "[36mGET /register.html HTTP/1.1[0m" 304 -
INFO _internal.py:113 127.0.0.1 - - [23/Sep/2020 14:03:15] "[37mGET /api/v1.0/image_codes/a1c7bb84-edde-4f45-bf1b-6484abaaacae HTTP/1.1[0m" 200 -
INFO _internal.py:113 127.0.0.1 - - [23/Sep/2020 14:03:16] "[36mGET /register.html HTTP/1.1[0m" 304 -
INFO _internal.py:113 127.0.0.1 - - [23/Sep/2020 14:03:17] "[37mGET /api/v1.0/image_codes/2e4f5aa8-b69f-4ad4-b452-cedd2ca4c489 HTTP/1.1[0m" 200 -
INFO _internal.py:113 127.0.0.1 - - [23/Sep/2020 14:03:19] "[36mGET /register.html HTTP/1.1[0m" 304 -
INFO _internal.py:113 127.0.0.1 - - [23/Sep/2020 14:03:19] "[37mGET /api/v1.0/image_codes/c0e19112-b63e-4c14-ac6d-a03e822e11c6 HTTP/1.1[0m" 200 -
INFO _internal.py:113 127.0.0.1 - - [23/Sep/2020 14:03:19] "[37mGET /favicon.ico HTTP/1.1[0m" 200 -
INFO _internal.py:113 127.0.0.1 - - [23/Sep/2020 14:03:19] "[36mGET /register.html HTTP/1.1[0m" 304 -
INFO _internal.py:113 127.0.0.1 - - [23/Sep/2020 14:03:19] "[37mGET /api/v1.0/image_codes/0b6855a6-ec04-46a0-b465-e40559e10113 HTTP/1.1[0m" 200 -
INFO _internal.py:113 127.0.0.1 - - [23/Sep/2020 14:03:19] "[37mGET /favicon.ico HTTP/1.1[0m" 200 -
INFO _internal.py:113 127.0.0.1 - - [23/Sep/2020 14:03:20] "[36mGET /register.html HTTP/1.1[0m" 304 -
INFO _internal.py:113 127.0.0.1 - - [23/Sep/2020 14:03:20] "[37mGET /api/v1.0/image_codes/cbe6c54f-bd10-4cdd-8267-deb664c20dfc HTTP/1.1[0m" 200 -
INFO _internal.py:113 127.0.0.1 - - [23/Sep/2020 14:03:20] "[37mGET /favicon.ico HTTP/1.1[0m" 200 -
INFO _internal.py:113 127.0.0.1 - - [23/Sep/2020 14:03:20] "[36mGET /register.html HTTP/1.1[0m" 304 -
INFO _internal.py:113 127.0.0.1 - - [23/Sep/2020 14:03:20] "[37mGET /api/v1.0/image_codes/8852e337-ae48-4687-8969-4ef6860c176c HTTP/1.1[0m" 200 -
INFO _internal.py:113 127.0.0.1 - - [23/Sep/2020 14:03:20] "[37mGET /favicon.ico HTTP/1.1[0m" 200 -
INFO _internal.py:113 127.0.0.1 - - [23/Sep/2020 14:03:21] "[36mGET /register.html HTTP/1.1[0m" 304 -
INFO _internal.py:113 127.0.0.1 - - [23/Sep/2020 14:03:21] "[37mGET /api/v1.0/image_codes/8e1f3194-b872-43e2-a473-1ae8f533f1c8 HTTP/1.1[0m" 200 -
INFO _internal.py:113 127.0.0.1 - - [23/Sep/2020 14:03:21] "[37mGET /favicon.ico HTTP/1.1[0m" 200 -
